<?xml version="1.0"?>
<robot name="humanoid">

  <link name="base_link">
    <visual>
      <geometry>
        <box size="0.2 0.3 0.5"/>
      </geometry>
      <material name="grey">
        <color rgba="0.5 0.5 0.5 1"/>
      </material>
    </visual>
  </link>

  <link name="head">
    <visual>
      <geometry>
        <sphere radius="0.15"/>
      </geometry>
      <material name="white">
        <color rgba="1 1 1 1"/>
      </material>
    </visual>
  </link>

  <joint name="neck_joint" type="revolute">
    <parent link="base_link"/>
    <child link="head"/>
    <origin xyz="0 0 0.3" rpy="0 0 0"/>
    <axis xyz="0 0 1"/>
    <limit lower="-1.57" upper="1.57" effort="10" velocity="1"/>
  </joint>

</robot>
